<?xml version='1.0'?>
<sdf version="1.9">
<model name="rover" canonical_link="Chassis_link">
  <joint name="Back Left Wheel Connection_link_joint" type="continuous">
    <pose relative_to="Left_Rocker_link">-0.040213 0.277630 -0.040843 -0.000000 1.570796 0.000000</pose>
    <parent>Left_Rocker_link</parent>
    <child>Back_Left_Wheel_Connection_link</child>
    <axis>
      <limit>
        <lower>0</lower>
        <upper>0</upper>
        <effort>0.000000</effort>
        <velocity>0.000000</velocity>
      </limit>
      <xyz>0.000000 0.000000 1.000000</xyz>
    </axis>
  </joint>
  <joint name="Back Left Wheel_link_joint" type="continuous">
    <pose relative_to="Back_Left_Wheel_Connection_link">-0.000277 -0.000140 -0.224216 0.000000 -1.570796 0.000000</pose>
    <parent>Back_Left_Wheel_Connection_link</parent>
    <child>Back_Left_Wheel_link</child>
    <axis>
      <limit>
        <lower>0</lower>
        <upper>0</upper>
        <effort>0.000000</effort>
        <velocity>0.000000</velocity>
      </limit>
      <xyz>0.000000 0.000000 1.000000</xyz>
    </axis>
  </joint>
  <joint name="Back Right Wheel_link_joint" type="continuous">
    <pose relative_to="Back_right_Wheel_Connection_link">-0.001001 -0.000072 -0.224364 0.000000 -1.570796 0.000000</pose>
    <parent>Back_right_Wheel_Connection_link</parent>
    <child>Back_Right_Wheel_link</child>
    <axis>
      <limit>
        <lower>0</lower>
        <upper>0</upper>
        <effort>0.000000</effort>
        <velocity>0.000000</velocity>
      </limit>
      <xyz>0.000000 0.000000 1.000000</xyz>
    </axis>
  </joint>
  <joint name="Back right Wheel Connection_link_joint" type="continuous">
    <pose relative_to="Right_Rocker_link">-0.039199 0.277668 0.039794 -0.000000 1.570796 0.000000</pose>
    <parent>Right_Rocker_link</parent>
    <child>Back_right_Wheel_Connection_link</child>
    <axis>
      <limit>
        <lower>0</lower>
        <upper>0</upper>
        <effort>0.000000</effort>
        <velocity>0.000000</velocity>
      </limit>
      <xyz>0.000000 0.000000 1.000000</xyz>
    </axis>
  </joint>
  <joint name="Front Left Wheel Connection_link_joint" type="continuous">
    <pose relative_to="Left_Rocker_link">-0.040213 -0.279250 -0.041051 -0.000000 1.570796 0.000000</pose>
    <parent>Left_Rocker_link</parent>
    <child>Front_Left_Wheel_Connection_link</child>
    <axis>
      <limit>
        <lower>0</lower>
        <upper>0</upper>
        <effort>0.000000</effort>
        <velocity>0.000000</velocity>
      </limit>
      <xyz>0.000000 0.000000 1.000000</xyz>
    </axis>
  </joint>
  <joint name="Front Left Wheel_link_joint" type="continuous">
    <pose relative_to="Front_Left_Wheel_Connection_link">-0.000405 0.000234 -0.224593 0.000000 -1.570796 0.000000</pose>
    <parent>Front_Left_Wheel_Connection_link</parent>
    <child>Front_Left_Wheel_link</child>
    <axis>
      <limit>
        <lower>0</lower>
        <upper>0</upper>
        <effort>0.000000</effort>
        <velocity>0.000000</velocity>
      </limit>
      <xyz>0.000000 0.000000 1.000000</xyz>
    </axis>
  </joint>
  <joint name="Front Right Wheel Connection_link_joint" type="continuous">
    <pose relative_to="Right_Rocker_link">-0.039199 -0.279811 0.039779 -0.000000 1.570796 0.000000</pose>
    <parent>Right_Rocker_link</parent>
    <child>Front_Right_Wheel_Connection_link</child>
    <axis>
      <limit>
        <lower>0</lower>
        <upper>0</upper>
        <effort>0.000000</effort>
        <velocity>0.000000</velocity>
      </limit>
      <xyz>0.000000 0.000000 1.000000</xyz>
    </axis>
  </joint>
  <joint name="Front Right Wheel_link_joint" type="continuous">
    <pose relative_to="Front_Right_Wheel_Connection_link">-0.001015 0.000984 -0.224364 -0.000000 -1.570796 0.000000</pose>
    <parent>Front_Right_Wheel_Connection_link</parent>
    <child>Front_Right_Wheel_link</child>
    <axis>
      <limit>
        <lower>0</lower>
        <upper>0</upper>
        <effort>0.000000</effort>
        <velocity>0.000000</velocity>
      </limit>
      <xyz>0.000000 0.000000 1.000000</xyz>
    </axis>
  </joint>
  <joint name="Left Rocker_link_joint" type="revolute">
    <pose relative_to="Chassis_link">0.316939 0.035009 -0.031693 0.000000 -1.570796 0.000000</pose>
    <parent>Chassis_link</parent>
    <child>Left_Rocker_link</child>
    <axis>
      <limit>
        <lower>-1.000000</lower>
        <upper>1.000000</upper>
        <effort>0.000000</effort>
        <velocity>0.000000</velocity>
      </limit>
      <xyz>0.000000 0.000000 1.000000</xyz>
    </axis>
  </joint>
  <joint name="Right Rocker_link_joint" type="revolute">
    <pose relative_to="Chassis_link">-0.326391 0.034904 -0.032707 0.000000 -1.570796 0.000000</pose>
    <parent>Chassis_link</parent>
    <child>Right_Rocker_link</child>
    <axis>
      <limit>
        <lower>-1.000000</lower>
        <upper>1.000000</upper>
        <effort>0.000000</effort>
        <velocity>0.000000</velocity>
      </limit>
      <xyz>0.000000 0.000000 1.000000</xyz>
    </axis>
  </joint>
  <link name="Back_Left_Wheel_Connection_link">
    <collision name="Back Left Wheel Connection_collision">
      <pose relative_to="Back_Left_Wheel_Connection_link">-0.000000 -0.000000 -0.000000 0.000000 0.000000 0.000000</pose>
      <geometry>
        <mesh>
          <uri>package://rover/meshes/dae/rover_assm.263.dae</uri>
          <scale>0.001020 0.001020 0.001020</scale>
        </mesh>
      </geometry>
      <surface>
        <contact/>
      </surface>
    </collision>
    <inertial>
      <inertia>
        <ixx>0.007968</ixx>
        <ixy>0.000000</ixy>
        <ixz>0.000000</ixz>
        <iyy>0.006673</iyy>
        <iyz>-0.002185</iyz>
        <izz>0.001483</izz>
      </inertia>
      <pose relative_to="Back_Left_Wheel_Connection_link">-0.034999 -0.000141 -0.080752 0.000000 0.000000 0.000000</pose>
      <mass>1.000000</mass>
    </inertial>
  </link>
  <link name="Back_Left_Wheel_link">
    <collision name="Back Left Wheel_collision">
      <pose relative_to="Back_Left_Wheel_link">-0.000149 -0.000000 -0.000229 -3.141593 -0.000000 -3.141593</pose>
      <geometry>
        <cylinder>
          <radius>0.152590</radius>
          <length>0.127483</length>
        </cylinder>
      </geometry>
      <surface>
        <contact/>
      </surface>
    </collision>
    <visual name="Back Left Wheel">
      <material>
        <diffuse>0.800000 0.800000 0.800000 1.000000</diffuse>
        <specular>0.400000 0.400000 0.400000 0.498039</specular>
        <emissive>0.000000 0.000000 0.000000 1.000000</emissive>
      </material>
      <pose relative_to="Back_Left_Wheel_link">-0.000148 -0.000000 -0.000229 -0.000000 1.570796 0.000000</pose>
      <geometry>
        <cylinder>
          <radius>0.063741</radius>
          <length>0.304673</length>
        </cylinder>
      </geometry>
    </visual>
  </link>
  <link name="Back_Right_Wheel_link">
    <collision name="Back Right Wheel_collision">
      <pose relative_to="Back_Right_Wheel_link">-0.000000 0.000000 0.000000 -3.141593 -0.000000 -3.141593</pose>
      <geometry>
        <cylinder>
          <radius>0.152590</radius>
          <length>0.127483</length>
        </cylinder>
      </geometry>
      <surface>
        <contact/>
      </surface>
    </collision>
    <visual name="Back Right Wheel">
      <material>
        <diffuse>0.800000 0.800000 0.800000 1.000000</diffuse>
        <specular>0.400000 0.400000 0.400000 0.498039</specular>
        <emissive>0.000000 0.000000 0.000000 1.000000</emissive>
      </material>
      <pose relative_to="Back_Right_Wheel_link">0.000000 0.000000 -0.000000 -0.000000 1.570796 0.000000</pose>
      <geometry>
        <cylinder>
          <radius>0.063741</radius>
          <length>0.304673</length>
        </cylinder>
      </geometry>
    </visual>
  </link>
  <link name="Back_right_Wheel_Connection_link">
    <collision name="Back right Wheel Connection_collision">
      <pose relative_to="Back_right_Wheel_Connection_link">-0.000000 0.000000 0.000000 0.000000 0.000000 0.000000</pose>
      <geometry>
        <mesh>
          <uri>package://rover/meshes/dae/rover_assm.273.dae</uri>
          <scale>0.001020 0.001020 0.001020</scale>
        </mesh>
      </geometry>
      <surface>
        <contact/>
      </surface>
    </collision>
    <inertial>
      <inertia>
        <ixx>0.007971</ixx>
        <ixy>0.000000</ixy>
        <ixz>-0.000000</ixz>
        <iyy>0.006675</iyy>
        <iyz>0.002187</iyz>
        <izz>0.001484</izz>
      </inertia>
      <pose relative_to="Back_right_Wheel_Connection_link">0.033951 -0.000071 -0.080752 0.000000 0.000000 0.000000</pose>
      <mass>1.000000</mass>
    </inertial>
  </link>
  <link name="Chassis_link">
    <collision name="Chassis_collision">
      <pose relative_to="Chassis_link">-0.000000 0.036421 0.000000 0.000000 0.000000 -0.000000</pose>
      <geometry>
        <box>
          <size>0.509469 0.629976 0.354739</size>
        </box>
      </geometry>
      <surface>
        <contact/>
      </surface>
    </collision>
    <inertial>
      <inertia>
        <ixx>0.045943</ixx>
        <ixy>-0.000000</ixy>
        <ixz>0.000000</ixz>
        <iyy>0.064649</iyy>
        <iyz>0.000000</iyz>
        <izz>0.064499</izz>
      </inertia>
      <pose relative_to="Chassis_link">0.000000 0.000000 0.000000 0.000000 0.000000 0.000000</pose>
      <mass>1.000000</mass>
    </inertial>
    <visual name="Chassis">
      <material>
        <diffuse>0.800000 0.800000 0.800000 1.000000</diffuse>
        <specular>0.011765 0.011765 0.011765 0.015686</specular>
        <emissive>0.000000 0.000000 0.000000 1.000000</emissive>
      </material>
      <pose relative_to="Chassis_link">0.000000 0.000000 0.000000 0.000000 0.000000 0.000000</pose>
      <geometry>
        <box>
          <size>0.524175 0.706562 0.525888</size>
        </box>
      </geometry>
    </visual>
  </link>
  <link name="Front_Left_Wheel_Connection_link">
    <collision name="Front Left Wheel Connection_collision">
      <pose relative_to="Front_Left_Wheel_Connection_link">0.000000 -0.000000 0.000000 0.000000 0.000000 0.000000</pose>
      <geometry>
        <mesh>
          <uri>file://rover/meshes/dae/rover_assm.266.dae</uri>
          <scale>0.001020 0.001020 0.001020</scale>
        </mesh>
      </geometry>
      <surface>
        <contact/>
      </surface>
    </collision>
    <inertial>
      <inertia>
        <ixx>0.007968</ixx>
        <ixy>0.000000</ixy>
        <ixz>0.000000</ixz>
        <iyy>0.006673</iyy>
        <iyz>-0.002185</iyz>
        <izz>0.001483</izz>
      </inertia>
      <pose relative_to="Front_Left_Wheel_Connection_link">-0.035207 0.000317 -0.080752 0.000000 0.000000 0.000000</pose>
      <mass>1.000000</mass>
    </inertial>
    <visual name="Front Left Wheel Connection">
      <material>
        <diffuse>0.800000 0.800000 0.800000 1.000000</diffuse>
        <specular>0.400000 0.400000 0.400000 0.498039</specular>
        <emissive>0.000000 0.000000 0.000000 1.000000</emissive>
      </material>
      <pose relative_to="Front_Left_Wheel_Connection_link">0.000000 -0.000000 0.000000 0.000000 0.000000 0.000000</pose>
      <geometry>
        <mesh>
          <uri>file://rover/meshes/dae/rover_assm.266.dae</uri>
          <scale>0.001020 0.001020 0.001020</scale>
        </mesh>
      </geometry>
    </visual>
  </link>
  <link name="Front_Left_Wheel_link">
    <collision name="Front Left Wheel_collision">
      <pose relative_to="Front_Left_Wheel_link">0.000149 -0.000000 0.000229 -3.141593 -0.000000 -3.141593</pose>
      <geometry>
        <cylinder>
          <radius>0.152957</radius>
          <length>0.127790</length>
        </cylinder>
      </geometry>
      <surface>
        <contact/>
      </surface>
    </collision>
    <inertial>
      <inertia>
        <ixx>0.008751</ixx>
        <ixy>-0.000000</ixy>
        <ixz>0.000000</ixz>
        <iyy>0.008751</iyy>
        <iyz>0.000000</iyz>
        <izz>0.002031</izz>
      </inertia>
      <pose relative_to="Front_Left_Wheel_link">0.000148 -0.000000 0.000229 0.000000 0.000000 0.000000</pose>
      <mass>1.000000</mass>
    </inertial>
    <visual name="Front Left Wheel">
      <material>
        <diffuse>0.800000 0.800000 0.800000 1.000000</diffuse>
        <specular>0.400000 0.400000 0.400000 0.498039</specular>
        <emissive>0.000000 0.000000 0.000000 1.000000</emissive>
      </material>
      <pose relative_to="Front_Left_Wheel_link">0.000149 -0.000000 0.000229 -0.000000 1.570796 0.000000</pose>
      <geometry>
        <cylinder>
          <radius>0.063742</radius>
          <length>0.304673</length>
        </cylinder>
      </geometry>
    </visual>
  </link>
  <link name="Front_Right_Wheel_Connection_link">
    <collision name="Front Right Wheel Connection_collision">
      <pose relative_to="Front_Right_Wheel_Connection_link">0.000000 -0.000000 0.000000 0.000000 0.000000 0.000000</pose>
      <geometry>
        <mesh>
          <uri>file://rover/meshes/dae/rover_assm.272.dae</uri>
          <scale>0.001020 0.001020 0.001020</scale>
        </mesh>
      </geometry>
      <surface>
        <contact/>
      </surface>
    </collision>
    <inertial>
      <inertia>
        <ixx>0.007971</ixx>
        <ixy>0.000000</ixy>
        <ixz>-0.000000</ixz>
        <iyy>0.006675</iyy>
        <iyz>0.002187</iyz>
        <izz>0.001484</izz>
      </inertia>
      <pose relative_to="Front_Right_Wheel_Connection_link">0.033936 0.000985 -0.080752 0.000000 0.000000 0.000000</pose>
      <mass>1.000000</mass>
    </inertial>
    <visual name="Front Right Wheel Connection">
      <material>
        <diffuse>0.800000 0.800000 0.800000 1.000000</diffuse>
        <specular>0.400000 0.400000 0.400000 0.498039</specular>
        <emissive>0.000000 0.000000 0.000000 1.000000</emissive>
      </material>
      <pose relative_to="Front_Right_Wheel_Connection_link">0.000000 -0.000000 0.000000 0.000000 0.000000 -0.000000</pose>
      <geometry>
        <mesh>
          <uri>file://rover/meshes/dae/rover_assm.272.dae</uri>
          <scale>0.001020 0.001020 0.001020</scale>
        </mesh>
      </geometry>
    </visual>
  </link>
  <link name="Front_Right_Wheel_link">
    <collision name="Front Right Wheel_collision">
      <pose relative_to="Front_Right_Wheel_link">-0.001154 -0.000002 -0.000037 0.000000 -0.000000 -0.000000</pose>
      <geometry>
        <cylinder>
          <radius>0.151841</radius>
          <length>0.126857</length>
        </cylinder>
      </geometry>
      <surface>
        <contact/>
      </surface>
    </collision>
    <inertial>
      <inertia>
        <ixx>0.008751</ixx>
        <ixy>0.000000</ixy>
        <ixz>0.000000</ixz>
        <iyy>0.008751</iyy>
        <iyz>-0.000000</iyz>
        <izz>0.002031</izz>
      </inertia>
      <pose relative_to="Front_Right_Wheel_link">0.000000 -0.000000 0.000000 0.000000 0.000000 0.000000</pose>
      <mass>1.000000</mass>
    </inertial>
    <visual name="Front Right Wheel">
      <material>
        <diffuse>0.800000 0.800000 0.800000 1.000000</diffuse>
        <specular>0.400000 0.400000 0.400000 0.498039</specular>
        <emissive>0.000000 0.000000 0.000000 1.000000</emissive>
      </material>
      <pose relative_to="Front_Right_Wheel_link">0.000000 -0.000000 0.000000 -0.000000 1.570796 0.000000</pose>
      <geometry>
        <cylinder>
          <radius>0.063741</radius>
          <length>0.304673</length>
        </cylinder>
      </geometry>
    </visual>
  </link>
  <link name="Left_Rocker_link">
    <collision name="Left Rocker_collision">
      <pose relative_to="Left_Rocker_link">-0.000000 -0.000000 0.000000 -0.000000 1.570796 0.000000</pose>
      <geometry>
        <mesh>
          <uri>file://rover/meshes/dae/rover_assm.277.dae</uri>
          <scale>0.001020 0.001020 0.001020</scale>
        </mesh>
      </geometry>
      <surface>
        <contact/>
      </surface>
    </collision>
    <inertial>
      <inertia>
        <ixx>0.001331</ixx>
        <ixy>-0.000094</ixy>
        <ixz>0.000210</ixz>
        <iyy>0.031629</iyy>
        <iyz>0.000565</iyz>
        <izz>0.031481</izz>
      </inertia>
      <pose relative_to="Left_Rocker_link">-0.042253 0.002366 -0.001819 0.000000 0.000000 0.000000</pose>
      <mass>1.000000</mass>
    </inertial>
    <visual name="Left Rocker">
      <material>
        <diffuse>0.800000 0.800000 0.800000 1.000000</diffuse>
        <specular>0.400000 0.400000 0.400000 0.498039</specular>
        <emissive>0.000000 0.000000 0.000000 1.000000</emissive>
      </material>
      <pose relative_to="Left_Rocker_link">-0.000000 -0.000000 0.000000 -0.000000 1.570796 0.000000</pose>
      <geometry>
        <mesh>
          <uri>file://rover/meshes/dae/rover_assm.277.dae</uri>
          <scale>0.001020 0.001020 0.001020</scale>
        </mesh>
      </geometry>
    </visual>
  </link>
  <link name="Right_Rocker_link">
    <collision name="Right Rocker_collision">
      <pose relative_to="Right_Rocker_link">-0.000000 0.000000 -0.000000 0.000000 1.570796 0.000000</pose>
      <geometry>
        <mesh>
          <uri>file://rover/meshes/dae/rover_assm.267.dae</uri>
          <scale>0.001020 0.001020 0.001020</scale>
        </mesh>
      </geometry>
      <surface>
        <contact/>
      </surface>
    </collision>
    <inertial>
      <inertia>
        <ixx>0.001330</ixx>
        <ixy>0.000096</ixy>
        <ixz>0.000215</ixz>
        <iyy>0.031632</iyy>
        <iyz>-0.000565</iyz>
        <izz>0.031485</izz>
      </inertia>
      <pose relative_to="Right_Rocker_link">-0.041239 0.002470 0.001819 0.000000 0.000000 0.000000</pose>
      <mass>1.000000</mass>
    </inertial>
    <visual name="Right Rocker">
      <material>
        <diffuse>0.800000 0.800000 0.800000 1.000000</diffuse>
        <specular>0.400000 0.400000 0.400000 0.498039</specular>
        <emissive>0.000000 0.000000 0.000000 1.000000</emissive>
      </material>
      <pose relative_to="Right_Rocker_link">-0.000000 0.000000 -0.000000 -0.000000 1.570796 0.000000</pose>
      <geometry>
        <mesh>
          <uri>file://rover/meshes/dae/rover_assm.267.dae</uri>
          <scale>0.001020 0.001020 0.001020</scale>
        </mesh>
      </geometry>
    </visual>
  </link>
</model>
</sdf>
