<?xml version='1.0'?>
<robot name="rover" version="1.0">
  
  <!-- Joint Definitions -->
  <joint name="base_footprint_joint" type="fixed">
    <parent link="base_link"/>
    <child link="base_footprint"/>
    <origin xyz="0 0 0" rpy="0 0 0"/>
  </joint>

  <link name="base_footprint">
  </link>
  <link name="base_link">
  </link>

  <joint name="chassis_joint" type="fixed">
    <origin rpy="0.0 0.0 0.0" xyz="0.0 0.0 0.45"/>
    <parent link="base_link"/>
    <child link="chassis_link"/>
    <origin xyz="0 0 0"/>
  </joint>

  <!-- WHEEL JOINTS -->
  <joint name="back_left_wheel_link_joint" type="continuous">
    <limit effort="1.5" velocity="20"/>
    <origin rpy="0.000000 -1.570796 0.000000" xyz="-0.001015 0.000984 -0.224364"/>
    <parent link="back_left_wheel_connection_link"/>
    <child link="back_left_wheel_link"/>
    <axis xyz="0.000000 0.000000 1.000000"/>
  </joint>
  <joint name="back_right_wheel_link_joint" type="continuous">
    <limit effort="1.5" velocity="20"/>
    <origin rpy="0.000000 -1.570796 0.000000" xyz="-0.001015 0.000984 -0.224364"/>
    <parent link="back_right_wheel_connection_link"/>
    <child link="back_right_wheel_link"/>
    <axis xyz="0.000000 0.000000 1.000000"/>
  </joint>
  <joint name="front_left_wheel_link_joint" type="continuous">
    <limit effort="1.5" velocity="20"/>
    <origin rpy="0.000000 -1.570796 0.000000" xyz="-0.001015 0.000984 -0.224364"/>
    <parent link="front_left_wheel_connection_link"/>
    <child link="front_left_wheel_link"/>
    <axis xyz="0.000000 0.000000 1.000000"/>
  </joint>
  <joint name="front_right_wheel_link_joint" type="continuous">
    <limit effort="1.5" velocity="20"/>
    <origin rpy="0.000000 -1.570796 0.000000" xyz="-0.001015 0.000984 -0.224364"/>
    <parent link="front_right_wheel_connection_link"/>
    <child link="front_right_wheel_link"/>
    <axis xyz="0.000000 0.000000 1.000000"/>
  </joint>

  <!-- CONNECTION JOINTS -->
  <joint name="back_right_wheel_connection_link_joint" type="continuous">
    <limit effort="5" lower="-2.1" upper="2.1" velocity="6.28"/>
    <origin rpy="-0.000000 1.570796 0.000000" xyz="-0.039199 0.277668 0.039794"/>
    <parent link="right_rocker_link"/>
    <child link="back_right_wheel_connection_link"/>
    <axis xyz="0.000000 0.000000 1.000000"/>
  </joint>
  <joint name="front_left_wheel_connection_link_joint" type="continuous">
    <limit effort="5" lower="-2.1" upper="2.1" velocity="6.28"/>
    <origin rpy="-0.000000 1.570796 0.000000" xyz="-0.040213 -0.279250 -0.041051"/>
    <parent link="left_rocker_link"/>
    <child link="front_left_wheel_connection_link"/>
    <axis xyz="0.000000 0.000000 1.000000"/>
  </joint>
  <joint name="front_right_wheel_connection_link_joint" type="continuous">
    <limit effort="5" lower="-2.1" upper="2.1" velocity="6.28"/>
    <origin rpy="-0.000000 1.570796 0.000000" xyz="-0.039199 -0.279811 0.039779"/>
    <parent link="right_rocker_link"/>
    <child link="front_right_wheel_connection_link"/>
    <axis xyz="0.000000 0.000000 1.000000"/>
  </joint>
  <joint name="back_left_wheel_connection_link_joint" type="continuous">
    <limit effort="5" lower="-2.1" upper="2.1" velocity="6.28"/>
    <origin rpy="-0.000000 1.570796 0.000000" xyz="-0.040213 0.277630 -0.040843"/>
    <parent link="left_rocker_link"/>
    <child link="back_left_wheel_connection_link"/>
    <axis xyz="0.000000 0.000000 1.000000"/>
  </joint>

  <!-- ROCKER JOINT -->
  <joint name="left_rocker_link_joint" type="fixed">
    <!-- <limit lower="-1.000000" upper="1.000000" effort="0.000000" velocity="0.000000"/> -->
    <origin rpy="0.000000 -1.570796 0.000000" xyz="0.316939 0.035009 -0.031693"/>
    <parent link="chassis_link"/>
    <child link="left_rocker_link"/>
    <axis xyz="0.000000 0.000000 1.000000"/>
  </joint>
  <joint name="right_rocker_link_joint" type="fixed">
    <!-- <limit lower="-1.000000" upper="1.000000" effort="0.000000" velocity="0.000000"/> -->
    <origin rpy="0.000000 -1.570796 0.000000" xyz="-0.326391 0.034904 -0.032707"/>
    <parent link="chassis_link"/>
    <child link="right_rocker_link"/>
    <axis xyz="0.000000 0.000000 1.000000"/>
  </joint>

  <!-- Link Definitions -->
  <link name="back_left_wheel_connection_link">
    <collision name="back_left_wheel_connection_collision">
      <origin rpy="0.000000 0.000000 0.000000" xyz="-0.000000 -0.000000 -0.000000"/>
      <geometry>
        <mesh filename="file:///home/fletcher/FLARE_ws/src/rover/meshes/dae/rover_assm.263.dae" scale="0.001020 0.001020 0.001020"/>
      </geometry>
    </collision>
    <inertial>
      <inertia ixx="0.007968" ixy="0.000000" ixz="0.000000" iyy="0.006673" iyz="-0.002185" izz="0.001483"/>
      <origin rpy="0.000000 0.000000 0.000000" xyz="-0.034999 -0.000141 -0.080752"/>
      <mass value="1.000000"/>
    </inertial>
    <visual name="back_left_wheel_connection">
      <origin rpy="0.000000 0.000000 0.000000" xyz="0.000000 -0.000000 0.000000"/>
      <material name="RockerMat"/>
      <geometry>
        <mesh filename="file:///home/fletcher/FLARE_ws/src/rover/meshes/dae/rover_assm.266.dae" scale="0.001020 0.001020 0.001020"/>
      </geometry>
    </visual>
  </link>
  <gazebo reference="back_left_wheel_connection_link">
    <material>Gazebo/Blue</material>
  </gazebo>
  <link name="back_left_wheel_link">
    <collision name="back_left_wheel_collision">
      <origin rpy="-3.141593 -0.000000 -3.141593" xyz="-0.000149 -0.000000 -0.000229"/>
      <geometry>
        <cylinder radius="0.152590" length="0.127483"/>
      </geometry>
    </collision>
    <inertial>
      <inertia ixx="0.045943" ixy="-0.000000" ixz="0.000000" iyy="0.064649" iyz="0.000000" izz="0.064499"/>
      <origin rpy="0.000000 0.000000 0.000000" xyz="0.000000 0.000000 0.000000"/>
      <mass value="1.000000"/>
    </inertial>
    <visual name="back_left_wheel">
      <origin rpy="-3.141593 -0.000000 -3.141593" xyz="-0.000 -0.000000 -0.000"/>
      <material name="Dirty Chrome"/>
      <geometry>
        <cylinder radius="0.152590" length="0.127483"/>
      </geometry>
    </visual>
  </link>
  <gazebo reference="back_left_wheel_link">
    <material>Gazebo/Black</material>
  </gazebo>
  <link name="back_right_wheel_link">
    <collision name="back_right_wheel_collision">
      <origin rpy="-3.141593 -0.000000 -3.141593" xyz="-0.000000 0.000000 0.000000"/>
      <geometry>
        <cylinder radius="0.152590" length="0.127483"/>
      </geometry>
    </collision>
    <inertial>
      <inertia ixx="0.045943" ixy="-0.000000" ixz="0.000000" iyy="0.064649" iyz="0.000000" izz="0.064499"/>
      <origin rpy="0.000000 0.000000 0.000000" xyz="0.000000 0.000000 0.000000"/>
      <mass value="1.000000"/>
    </inertial>
    <visual name="back_right_wheel">
      <origin rpy="-3.141593 -0.000000 -3.141593" xyz="0.000000 0.000000 -0.000000"/>
      <material name="Dirty Chrome"/>
      <geometry>
        <cylinder radius="0.152590" length="0.127483"/>
      </geometry>
    </visual>
  </link>
  <gazebo reference="back_right_wheel_link">
    <material>Gazebo/Black</material>
  </gazebo>
  <link name="back_right_wheel_connection_link">
    <collision name="back_right_wheel_connection_collision">
      <origin rpy="0.000000 0.000000 0.000000" xyz="-0.000000 0.000000 0.000000"/>
      <geometry>
        <mesh filename="file:///home/fletcher/FLARE_ws/src/rover/meshes/dae/rover_assm.273.dae" scale="0.001020 0.001020 0.001020"/>
      </geometry>
    </collision>
    <inertial>
      <inertia ixx="0.007971" ixy="0.000000" ixz="-0.000000" iyy="0.006675" iyz="0.002187" izz="0.001484"/>
      <origin rpy="0.000000 0.000000 0.000000" xyz="0.033951 -0.000071 -0.080752"/>
      <mass value="1.000000"/>
    </inertial>
    <visual name="back_right_wheel_connection">
      <origin rpy="0.000000 0.000000 0.000000" xyz="0.000000 -0.000000 0.000000"/>
      <material name="RockerMat"/>
      <geometry>
        <mesh filename="file:///home/fletcher/FLARE_ws/src/rover/meshes/dae/rover_assm.272.dae" scale="0.001020 0.001020 0.001020"/>
      </geometry>
    </visual>
  </link>
  <gazebo reference="back_right_wheel_connection_link">
    <material>Gazebo/Blue</material>
  </gazebo>
  <link name="chassis_link">
    <collision name="chassis_collision">
      <origin rpy="0.000000 0.000000 -0.000000" xyz="-0.000000 0.036421 0.000000"/>
      <geometry>
        <box size="0.509469 0.629976 0.354739"/>
      </geometry>
    </collision>
    <inertial>
      <inertia ixx="0.045943" ixy="-0.000000" ixz="0.000000" iyy="0.064649" iyz="0.000000" izz="0.064499"/>
      <origin rpy="0.000000 0.000000 0.000000" xyz="0.000000 0.000000 0.000000"/>
      <mass value="1.000000"/>
    </inertial>
    <visual name="chassis">
      <origin rpy="0.000000 0.000000 0.000000" xyz="0.000000 0.000000 0.000000"/>
      <material name="MLI Foil for chassis"/>
      <geometry>
        <box size="0.509469 0.629976 0.354739"/>
      </geometry>
    </visual>
  </link>
  <gazebo reference="chassis_link">
    <material>Gazebo/Orange</material>
  </gazebo>
  <link name="front_left_wheel_connection_link">
    <collision name="front_left_wheel_connection_collision">
      <origin rpy="0.000000 0.000000 0.000000" xyz="0.000000 -0.000000 0.000000"/>
      <geometry>
        <mesh filename="file:///home/fletcher/FLARE_ws/src/rover/meshes/dae/rover_assm.266.dae" scale="0.001020 0.001020 0.001020"/>
      </geometry>
    </collision>
    <inertial>
      <inertia ixx="0.007968" ixy="0.000000" ixz="0.000000" iyy="0.006673" iyz="-0.002185" izz="0.001483"/>
      <origin rpy="0.000000 0.000000 0.000000" xyz="-0.035207 0.000317 -0.080752"/>
      <mass value="1.000000"/>
    </inertial>
    <visual name="front_left_wheel_connection">
      <origin rpy="0.000000 0.000000 0.000000" xyz="0.000000 -0.000000 0.000000"/>
      <material name="RockerMat"/>
      <geometry>
        <mesh filename="file:///home/fletcher/FLARE_ws/src/rover/meshes/dae/rover_assm.266.dae" scale="0.001020 0.001020 0.001020"/>
      </geometry>
    </visual>
  </link>
  <gazebo reference="front_left_wheel_connection_link">
    <material>Gazebo/Blue</material>
  </gazebo>
  <link name="front_left_wheel_link">
    <collision name="front_left_wheel_collision">
      <origin rpy="-3.141593 -0.000000 -3.141593" xyz="0.000149 -0.000000 0.000229"/>
      <geometry>
        <cylinder radius="0.152957" length="0.127790"/>
      </geometry>
    </collision>
    <inertial>
      <inertia ixx="0.008751" ixy="-0.000000" ixz="0.000000" iyy="0.008751" iyz="0.000000" izz="0.002031"/>
      <origin rpy="0.000000 0.000000 0.000000" xyz="0.000148 -0.000000 0.000229"/>
      <mass value="1.000000"/>
    </inertial>
    <visual name="front_left_wheel">
      <origin rpy="-3.141593 -0.000000 -3.141593" xyz="0.000149 -0.000000 0.000229"/>
      <material name="Dirty Chrome"/>
      <geometry>
        <cylinder radius="0.152590" length="0.127483"/>
      </geometry>
    </visual>
  </link>
  <gazebo reference="front_left_wheel_link">
    <material>Gazebo/Black</material>
  </gazebo>
  <link name="front_right_wheel_connection_link">
    <collision name="front_right_wheel_connection_collision">
      <origin rpy="0.000000 0.000000 0.000000" xyz="0.000000 -0.000000 0.000000"/>
      <geometry>
        <mesh filename="file:///home/fletcher/FLARE_ws/src/rover/meshes/dae/rover_assm.272.dae" scale="0.001020 0.001020 0.001020"/>
      </geometry>
    </collision>
    <inertial>
      <inertia ixx="0.007971" ixy="0.000000" ixz="-0.000000" iyy="0.006675" iyz="0.002187" izz="0.001484"/>
      <origin rpy="0.000000 0.000000 0.000000" xyz="0.033936 0.000985 -0.080752"/>
      <mass value="1.000000"/>
    </inertial>
    <visual name="front_right_wheel_connection">
      <origin rpy="0.000000 0.000000 -0.000000" xyz="0.000000 -0.000000 0.000000"/>
      <material name="RockerMat"/>
      <geometry>
        <mesh filename="file:///home/fletcher/FLARE_ws/src/rover/meshes/dae/rover_assm.272.dae" scale="0.001020 0.001020 0.001020"/>
      </geometry>
    </visual>
  </link>
  <gazebo reference="front_right_wheel_connection_link">
    <material>Gazebo/Blue</material>
  </gazebo>
  <link name="front_right_wheel_link">
    <collision name="front_right_wheel_collision">
      <origin rpy="0.000000 -0.000000 -0.000000" xyz="-0.001154 -0.000002 -0.000037"/>
      <geometry>
        <cylinder radius="0.151841" length="0.126857"/>
      </geometry>
    </collision>
    <inertial>
      <inertia ixx="0.008751" ixy="0.000000" ixz="0.000000" iyy="0.008751" iyz="-0.000000" izz="0.002031"/>
      <origin rpy="0.000000 0.000000 0.000000" xyz="0.000000 -0.000000 0.000000"/>
      <mass value="1.000000"/>
    </inertial>
    <visual name="front_right_wheel">
      <origin rpy="-3.141593 -0.000000 -3.141593" xyz="0.000000 -0.000000 0.000000"/>
      <material name="Dirty Chrome"/>
      <geometry>
        <cylinder radius="0.152590" length="0.127483"/>
      </geometry>
    </visual>
  </link>
  <gazebo reference="front_right_wheel_link">
    <material>Gazebo/Black</material>
  </gazebo>
  <link name="left_rocker_link">
    <collision name="left_rocker_collision">
      <origin rpy="-0.000000 1.570796 0.000000" xyz="-0.000000 -0.000000 0.000000"/>
      <geometry>
        <mesh filename="file:///home/fletcher/FLARE_ws/src/rover/meshes/dae/rover_assm.277.dae" scale="0.001020 0.001020 0.001020"/>
      </geometry>
    </collision>
    <inertial>
      <inertia ixx="0.001331" ixy="-0.000094" ixz="0.000210" iyy="0.031629" iyz="0.000565" izz="0.031481"/>
      <origin rpy="0.000000 0.000000 0.000000" xyz="-0.042253 0.002366 -0.001819"/>
      <mass value="1.000000"/>
    </inertial>
    <visual name="left_rocker">
      <origin rpy="-0.000000 1.570796 0.000000" xyz="-0.000000 -0.000000 0.000000"/>
      <material name="RockerMat"/>
      <geometry>
        <mesh filename="file:///home/fletcher/FLARE_ws/src/rover/meshes/dae/rover_assm.277.dae" scale="0.001020 0.001020 0.001020"/>
      </geometry>
    </visual>
  </link>
  <gazebo reference="left_rocker_link">
    <material>Gazebo/White</material>
  </gazebo>
  <link name="right_rocker_link">
    <collision name="right_rocker_collision">
      <origin rpy="0.000000 1.570796 0.000000" xyz="-0.000000 0.000000 -0.000000"/>
      <geometry>
        <mesh filename="file:///home/fletcher/FLARE_ws/src/rover/meshes/dae/rover_assm.267.dae" scale="0.001020 0.001020 0.001020"/>
      </geometry>
    </collision>
    <inertial>
      <inertia ixx="0.001330" ixy="0.000096" ixz="0.000215" iyy="0.031632" iyz="-0.000565" izz="0.031485"/>
      <origin rpy="0.000000 0.000000 0.000000" xyz="-0.041239 0.002470 0.001819"/>
      <mass value="1.000000"/>
    </inertial>
    <visual name="right_rocker">
      <origin rpy="-0.000000 1.570796 0.000000" xyz="-0.000000 0.000000 -0.000000"/>
      <material name="RockerMat"/>
      <geometry>
        <mesh filename="file:///home/fletcher/FLARE_ws/src/rover/meshes/dae/rover_assm.267.dae" scale="0.001020 0.001020 0.001020"/>
      </geometry>
    </visual>
  </link>
  <gazebo reference="right_rocker_link">
    <material>Gazebo/White</material>
  </gazebo>

  <!-- Lidar -->
  <!-- <joint name="laser_joint" type="fixed">
    <parent link="chassis_link"/>
    <child link="laser_frame"/>
    <origin xyz="0 0.27 0.2" rpy="0 0 0"/>
  </joint>

  <link name="laser_frame">
    <visual>
      <geometry>
        <cylinder radius="0.05" length="0.04"/>
      </geometry>
    </visual>
    <collision>
      <geometry>
        <cylinder radius="0.05" length="0.04"/>
      </geometry>
    </collision>
    <inertial>
      <inertia ixx="4.17e-05" ixy="0.0" ixz="0.0" iyy="4.17e-05" iyz="0.0" izz="1.25e-06"/>
      <origin xyz="0 0 0" rpy="0 0 0"/>
      <mass value="0.050"/>
    </inertial>
  </link> -->
  
  <!-- <gazebo reference="laser_frame">
    <sensor type="ray" name="laser_frame-VLP16">
      <pose>0 0 0 0 0 0</pose>
      <visualize>true</visualize>
      <update_rate>10</update_rate>
      <ray>
        <scan>
          <horizontal>
            <samples>200</samples>
            <resolution>1</resolution>
            <min_angle>0.698132</min_angle>
            <max_angle>2.44346</max_angle>
          </horizontal>
          <vertical>
            <samples>50</samples>
            <resolution>1</resolution>
            <min_angle>-0.6108651</min_angle>
            <max_angle>0.261799</max_angle>
          </vertical>
        </scan>
        <range>
          <min>0.9</min>
          <max>10.0</max>
          <resolution>0.001</resolution>
        </range>
        <noise>
          <type>gaussian</type>
          <mean>0.0</mean>
          <stddev>0.0</stddev>
        </noise>
      </ray>
      <plugin name="gazebo_ros_laser_controller" filename="libgazebo_ros_velodyne_laser.so">
        <topicName>/velodyne_points</topicName>
        <frameName>velodyne</frameName>
        <min_range>0.9</min_range>
        <max_range>10.0</max_range>
        <gaussianNoise>0.008</gaussianNoise>
      </plugin>
    </sensor>
  </gazebo> -->

  <!-- ROS2 Control -->
  <ros2_control name="GazeboSystem" type="system">
    <hardware>
      <plugin>gazebo_ros2_control/GazeboSystem</plugin>
    </hardware>
    <!-- Wheels -->
    <joint name="front_left_wheel_link_joint">
      <command_interface name="velocity">
        <param name="min">-10</param>
        <param name="max">10</param>
      </command_interface>
      <state_interface name="velocity"/>
      <state_interface name="position"/>
    </joint>
    <joint name="front_right_wheel_link_joint">
      <command_interface name="velocity">
        <param name="min">-10</param>
        <param name="max">10</param>
      </command_interface>
      <state_interface name="velocity"/>
      <state_interface name="position"/>
    </joint>
    <joint name="back_left_wheel_link_joint">
      <command_interface name="velocity">
        <param name="min">-10</param>
        <param name="max">10</param>
      </command_interface>
      <state_interface name="velocity"/>
      <state_interface name="position"/>
    </joint>
    <joint name="back_right_wheel_link_joint">
      <command_interface name="velocity">
        <param name="min">-10</param>
        <param name="max">10</param>
      </command_interface>
      <state_interface name="velocity"/>
      <state_interface name="position"/>
    </joint>
    <!-- Connectors -->
    <joint name="front_left_wheel_connection_link_joint">
      <command_interface name="position">
        <param name="min">-10</param>
        <param name="max">10</param>
      </command_interface>
      <state_interface name="velocity"/>
      <state_interface name="position"/>
    </joint>
    <joint name="front_right_wheel_connection_link_joint">
      <command_interface name="position">
        <param name="min">-10</param>
        <param name="max">10</param>
      </command_interface>
      <state_interface name="velocity"/>
      <state_interface name="position"/>
    </joint>
    <joint name="back_left_wheel_connection_link_joint">
      <command_interface name="position">
        <param name="min">-10</param>
        <param name="max">10</param>
      </command_interface>
      <state_interface name="velocity"/>
      <state_interface name="position"/>
    </joint>
    <joint name="back_right_wheel_connection_link_joint">
      <command_interface name="position">
        <param name="min">-10</param>
        <param name="max">10</param>
      </command_interface>
      <state_interface name="velocity"/>
      <state_interface name="position"/>
    </joint>
    <!-- Rockers -->
    <!-- <joint name="left_rocker_link_joint">
      <command_interface name="velocity">
        <param name="min">-10</param>
        <param name="max">10</param>
      </command_interface>
      <state_interface name="velocity"/>
      <state_interface name="position"/>
    </joint>
    <joint name="right_rocker_link_joint">
      <command_interface name="velocity">
        <param name="min">-10</param>
        <param name="max">10</param>
      </command_interface>
      <state_interface name="velocity"/>
      <state_interface name="position"/>
    </joint> -->
  </ros2_control>
  <gazebo>
    <plugin name="gazebo_ros2_control" filename="libgazebo_ros2_control.so">
      <parameters>/home/fletcher/FLARE_ws/install/rover/share/rover/config/controllers.yaml</parameters>
      <!-- <parameters>$(find rover)/config/gaz_ros2_ctl_use_sim.yaml</parameters> -->
    </plugin>
  </gazebo>

  <!-- DEPTH CAMERA -->
  <joint name="camera_joint" type="fixed">
    <parent link="chassis_link"/>
    <child link="camera_link"/>
    <origin xyz="0 0.35 -0.1" rpy="0 0.523599 1.570796"/>
  </joint>

  <link name="camera_link">
    <visual>
      <geometry>
        <box size="0.010 0.03 0.03"/>
      </geometry>
      <material name="RockerMat"/>
    </visual>
  </link>

  <joint name="camera_optical_joint" type="fixed">
    <parent link="camera_link"/>
    <child link="camera_link_optical"/>
    <origin xyz="0 0 0" rpy="1.570796 3.141592 1.570796"/>
  </joint>

  <link name="camera_link_optical"></link>

  <gazebo reference="camera_link">

    <sensor name="camera" type="depth">
      <pose> 0 0 0 0 0 0 </pose>
      <visualize>true</visualize>
      <update_rate>10</update_rate>
      <camera>
        <horizontal_fov>1.5</horizontal_fov>
        <image>
          <format>B8G8R8</format>
          <width>1490</width>
          <height>1080</height>
        </image>
        <clip>
          <near>0.02</near>
          <far>8.0</far>
        </clip>
      </camera>
      <plugin name="camera_controller" filename="libgazebo_ros_camera.so">
        <frame_name>camera_link_optical</frame_name>
        <min_depth>0.01</min_depth>
        <max_depth>10.0</max_depth>
      </plugin>
    </sensor>
  </gazebo>

  <!-- Material Definitions -->
  <material name="Dirty Chrome">
    <color rgba="0.800000 0.800000 0.800000 1.000000"/>
  </material>
  <material name="MLI Foil for chassis">
    <color rgba="0.800000 0.800000 0.800000 1.000000"/>
  </material>
  <material name="RockerMat">
    <color rgba="0.800000 0.800000 0.800000 1.000000"/>
  </material>
</robot>
